Workbook

Sheet DATA
A1: Fecha | B1: Ruta | C1: Cliente | D1: Nombre | E1: Motivo No Entregado | F1: Unidad Negocio | G1: Responsable | H1: Eventos | I1: Cajas | J1: UNIDAD DE NEGOCIO FINAL | K1: LATITUD | L1: LONGITUD | M1: EMPRESARIO
A2: 46083 | B2: BK3712 | C2: 10200237 | D2: Carrillo Coll Cardenas, Benjamin Julio | E2: C9 NEN-Error carga | F2: Off Tradicional | G2: Logistic | H2: 1 | I2: 2 | J2: =VLOOKUP(C2,MAESTRO_CLIENTES!A:H,8,0) -> GIOVANY RUBINOS VILCHEZ | K2: =VLOOKUP(C2,MAESTRO_CLIENTES!A:Y,9,0) -> -12.03404 | L2: =VLOOKUP(C2,MAESTRO_CLIENTES!A:Y,10,0) -> -77.03095 | M2: =VLOOKUP(B2,Hoja1!B:C,2,0) -> SEGSOL S.A.C.
A3: 46083 | B3: BK3712 | C3: 11712811 | D3: Llampi, Juliana | E3: B4 NEN-Ausente | F3: Off Tradicional | G3: Customer | H3: 1 | I3: 4 | J3: =VLOOKUP(C3,MAESTRO_CLIENTES!A:H,8,0) -> GIOVANY RUBINOS VILCHEZ | K3: =VLOOKUP(C3,MAESTRO_CLIENTES!A:Y,9,0) -> -12.033006 | L3: =VLOOKUP(C3,MAESTRO_CLIENTES!A:Y,10,0) -> -77.029724 | M3: =VLOOKUP(B3,Hoja1!B:C,2,0) -> SEGSOL S.A.C.
A4: 46083 | B4: BK3712 | C4: 10932255 | D4: Mayorsa S.A. | E4: B8 NEN-Mal facturado | F4: Off Moderno | G4: Sales | H4: 1 | I4: 120 | J4: =VLOOKUP(C4,MAESTRO_CLIENTES!A:H,8,0) -> CHAVEZ HOLGUIN KENNER | K4: =VLOOKUP(C4,MAESTRO_CLIENTES!A:Y,9,0) -> -12.039674 | L4: =VLOOKUP(C4,MAESTRO_CLIENTES!A:Y,10,0) -> -77.032652 | M4: =VLOOKUP(B4,Hoja1!B:C,2,0) -> SEGSOL S.A.C.
A5: 46083 | B5: BK3712 | C5: 13942913 | D5: NECOCHEA FERNANDEZ, JOHAIRA JACKELIN | E5: C2 NEN-No ubicado | F5: Off Tradicional | G5: Sales | H5: 1 | I5: 3 | J5: =VLOOKUP(C5,MAESTRO_CLIENTES!A:H,8,0) -> GIOVANY RUBINOS VILCHEZ | K5: =VLOOKUP(C5,MAESTRO_CLIENTES!A:Y,9,0) -> -12.034149 | L5: =VLOOKUP(C5,MAESTRO_CLIENTES!A:Y,10,0) -> -77.028757 | M5: =VLOOKUP(B5,Hoja1!B:C,2,0) -> SEGSOL S.A.C.
A6: 46083 | B6: BK3712 | C6: 13327315 | D6: De La Cruz Masias, Alexander | E6: B4 NEN-Ausente | F6: On Tradicional | G6: Customer | H6: 2 | I6: 1.416666 | J6: =VLOOKUP(C6,MAESTRO_CLIENTES!A:H,8,0) -> ESTEBAN FERNANDEZ | K6: =VLOOKUP(C6,MAESTRO_CLIENTES!A:Y,9,0) -> -12.029749 | L6: =VLOOKUP(C6,MAESTRO_CLIENTES!A:Y,10,0) -> -77.030003 | M6: =VLOOKUP(B6,Hoja1!B:C,2,0) -> SEGSOL S.A.C.
A7: 46083 | B7: BK3712 | C7: 10236992 | D7: Pucuhuayla Solis, Gloria | E7: C9 NEN-Error carga | F7: Off Tradicional | G7: Logistic | H7: 1 | I7: 3 | J7: =VLOOKUP(C7,MAESTRO_CLIENTES!A:H,8,0) -> GIOVANY RUBINOS VILCHEZ | K7: =VLOOKUP(C7,MAESTRO_CLIENTES!A:Y,9,0) -> -12.033857 | L7: =VLOOKUP(C7,MAESTRO_CLIENTES!A:Y,10,0) -> -77.029907 | M7: =VLOOKUP(B7,Hoja1!B:C,2,0) -> SEGSOL S.A.C.
A8: 46083 | B8: BK3712 | C8: 12903380 | D8: Taipe Ortega, Bernardo | E8: B4 NEN-Ausente | F8: Off Tradicional | G8: Customer | H8: 1 | I8: 5 | J8: =VLOOKUP(C8,MAESTRO_CLIENTES!A:H,8,0) -> GIOVANY RUBINOS VILCHEZ | K8: =VLOOKUP(C8,MAESTRO_CLIENTES!A:Y,9,0) -> -12.03281 | L8: =VLOOKUP(C8,MAESTRO_CLIENTES!A:Y,10,0) -> -77.029673 | M8: =VLOOKUP(B8,Hoja1!B:C,2,0) -> SEGSOL S.A.C.
A9: 46083 | B9: BK3712 | C9: 13952187 | D9: Lilia Noelita Silva Villegas | E9: C9 NEN-Error carga | F9: Off Tradicional | G9: Logistic | H9: 1 | I9: 1 | J9: =VLOOKUP(C9,MAESTRO_CLIENTES!A:H,8,0) -> GIOVANY RUBINOS VILCHEZ | K9: =VLOOKUP(C9,MAESTRO_CLIENTES!A:Y,9,0) -> -12.029825 | L9: =VLOOKUP(C9,MAESTRO_CLIENTES!A:Y,10,0) -> -77.031842 | M9: =VLOOKUP(B9,Hoja1!B:C,2,0) -> SEGSOL S.A.C.
A10: 46083 | B10: BK3712 | C10: 14144216 | D10: RIOS DIONICIO, LUIS | E10: B3 NEN-Sin dinero | F10: Off Tradicional | G10: Customer | H10: 1 | I10: 4 | J10: =VLOOKUP(C10,MAESTRO_CLIENTES!A:H,8,0) -> GIOVANY RUBINOS VILCHEZ | K10: =VLOOKUP(C10,MAESTRO_CLIENTES!A:Y,9,0) -> -12.034322 | L10: =VLOOKUP(C10,MAESTRO_CLIENTES!A:Y,10,0) -> -77.039389 | M10: =VLOOKUP(B10,Hoja1!B:C,2,0) -> SEGSOL S.A.C.
A11: 46083 | B11: BK3760 | C11: 10262404 | D11: Supermercados Peruanos S.A. | E11: C1 NEN-Fuera de horario | F11: Off Moderno | G11: Logistic | H11: 2 | I11: 53 | J11: =VLOOKUP(C11,MAESTRO_CLIENTES!A:H,8,0) -> CHAVEZ HOLGUIN KENNER | K11: =VLOOKUP(C11,MAESTRO_CLIENTES!A:Y,9,0) -> -12.075344 | L11: =VLOOKUP(C11,MAESTRO_CLIENTES!A:Y,10,0) -> -77.053136 | M11: =VLOOKUP(B11,Hoja1!B:C,2,0) -> CORPORACION BREXIMAR S.A.C.
A12: 46083 | B12: BK3760 | C12: 11208713 | D12: Supermercados Peruanos S.A. | E12: C1 NEN-Fuera de horario | F12: Off Moderno | G12: Logistic | H12: 2 | I12: 78 | J12: =VLOOKUP(C12,MAESTRO_CLIENTES!A:H,8,0) -> CHAVEZ HOLGUIN KENNER | K12: =VLOOKUP(C12,MAESTRO_CLIENTES!A:Y,9,0) -> -12.065779 | L12: =VLOOKUP(C12,MAESTRO_CLIENTES!A:Y,10,0) -> -77.04831 | M12: =VLOOKUP(B12,Hoja1!B:C,2,0) -> CORPORACION BREXIMAR S.A.C.
A13: 46083 | B13: BK3760 | C13: 12174702 | D13: Palomino Rojas, Maria | E13: B3 NEN-Sin dinero | F13: Off Tradicional | G13: Customer | H13: 1 | I13: 1 | J13: =VLOOKUP(C13,MAESTRO_CLIENTES!A:H,8,0) -> HEIGER DONADONY CESPEDES CESPEDES | K13: =VLOOKUP(C13,MAESTRO_CLIENTES!A:Y,9,0) -> -12.067067 | L13: =VLOOKUP(C13,MAESTRO_CLIENTES!A:Y,10,0) -> -77.047023 | M13: =VLOOKUP(B13,Hoja1!B:C,2,0) -> CORPORACION BREXIMAR S.A.C.
... A167: 46084 | B167: BK3778 | C167: 13339689 | D167: Huatarunco Suclupe, Martin | E167: B8 NEN-Mal facturado | F167: Off Tradicional | G167: Sales | H167: 1 | I167: 11.25 | J167: =VLOOKUP(C167,MAESTRO_CLIENTES!A:H,8,0) -> DARCY JIMENEZ | K167: =VLOOKUP(C167,MAESTRO_CLIENTES!A:Y,9,0) -> -11.995579 | L167: =VLOOKUP(C167,MAESTRO_CLIENTES!A:Y,10,0) -> -77.004111 | M167: =VLOOKUP(B167,Hoja1!B:C,2,0) -> F & B ANDINA SAC
A168: 46084 | B168: BK3778 | C168: 13904865 | D168: #N/A | E168: C2 NEN-No ubicado | F168: #N/A | G168: Sales | H168: 1 | I168: 3 | J168: =VLOOKUP(C168,MAESTRO_CLIENTES!A:H,8,0) -> #N/A | K168: =VLOOKUP(C168,MAESTRO_CLIENTES!A:Y,9,0) -> #N/A | L168: =VLOOKUP(C168,MAESTRO_CLIENTES!A:Y,10,0) -> #N/A | M168: =VLOOKUP(B168,Hoja1!B:C,2,0) -> F & B ANDINA SAC
A169: 46084 | B169: BK3778 | C169: 14079060 | D169: Juan De Dios Canteno, Aurelio | E169: B6 NEN-No hizo pedido | F169: Off Tradicional | G169: Sales | H169: 1 | I169: 1 | J169: =VLOOKUP(C169,MAESTRO_CLIENTES!A:H,8,0) -> DARCY JIMENEZ | K169: =VLOOKUP(C169,MAESTRO_CLIENTES!A:Y,9,0) -> -11.998217 | L169: =VLOOKUP(C169,MAESTRO_CLIENTES!A:Y,10,0) -> -77.002956 | M169: =VLOOKUP(B169,Hoja1!B:C,2,0) -> F & B ANDINA SAC
A170: 46084 | B170: BK3778 | C170: 14226840 | D170: Nino De Guzman Navarro, Izumy Lourdes | E170: B1 NEN-Cerrado | F170: Off Tradicional | G170: Customer | H170: 1 | I170: 4 | J170: =VLOOKUP(C170,MAESTRO_CLIENTES!A:H,8,0) -> DARCY JIMENEZ | K170: =VLOOKUP(C170,MAESTRO_CLIENTES!A:Y,9,0) -> -12.005488 | L170: =VLOOKUP(C170,MAESTRO_CLIENTES!A:Y,10,0) -> -77.005337 | M170: =VLOOKUP(B170,Hoja1!B:C,2,0) -> F & B ANDINA SAC
A171: 46084 | B171: BK3722 | C171: 12754169 | D171: Zuniga Zapata, Alicia | E171: B1 NEN-Cerrado | F171: Off Tradicional | G171: Customer | H171: 1 | I171: 33 | J171: =VLOOKUP(C171,MAESTRO_CLIENTES!A:H,8,0) -> DARCY JIMENEZ | K171: =VLOOKUP(C171,MAESTRO_CLIENTES!A:Y,9,0) -> -12.033048 | L171: =VLOOKUP(C171,MAESTRO_CLIENTES!A:Y,10,0) -> -77.005672 | M171: =VLOOKUP(B171,Hoja1!B:C,2,0) -> JRGRODVAL DISTRIBUCIONES S.A.C.
A172: 46084 | B172: BK3722 | C172: 12886817 | D172: Perez Trauco, David Gonzalo | E172: C5 NEN-Atrib Camión o Ruta | F172: Off Tradicional | G172: Logistic | H172: 1 | I172: 1 | J172: =VLOOKUP(C172,MAESTRO_CLIENTES!A:H,8,0) -> DARCY JIMENEZ | K172: =VLOOKUP(C172,MAESTRO_CLIENTES!A:Y,9,0) -> -12.035869 | L172: =VLOOKUP(C172,MAESTRO_CLIENTES!A:Y,10,0) -> -77.005761 | M172: =VLOOKUP(B172,Hoja1!B:C,2,0) -> JRGRODVAL DISTRIBUCIONES S.A.C.
A173: 46084 | B173: BK3722 | C173: 12943386 | D173: ChacÃ³n Medina, Noris Luzmeri | E173: B1 NEN-Cerrado | F173: Off Tradicional | G173: Customer | H173: 1 | I173: 18 | J173: =VLOOKUP(C173,MAESTRO_CLIENTES!A:H,8,0) -> DARCY JIMENEZ | K173: =VLOOKUP(C173,MAESTRO_CLIENTES!A:Y,9,0) -> -12.040144 | L173: =VLOOKUP(C173,MAESTRO_CLIENTES!A:Y,10,0) -> -76.996205 | M173: =VLOOKUP(B173,Hoja1!B:C,2,0) -> JRGRODVAL DISTRIBUCIONES S.A.C.
A174: 46084 | B174: BK3764 | C174: 12112910 | D174: Eugenio Revilla, Melisa Dorelly | E174: B1 NEN-Cerrado | F174: Off Tradicional | G174: Customer | H174: 1 | I174: 6 | J174: =VLOOKUP(C174,MAESTRO_CLIENTES!A:H,8,0) -> DARCY JIMENEZ | K174: =VLOOKUP(C174,MAESTRO_CLIENTES!A:Y,9,0) -> -11.990313 | L174: =VLOOKUP(C174,MAESTRO_CLIENTES!A:Y,10,0) -> -77.003125 | M174: =VLOOKUP(B174,Hoja1!B:C,2,0) -> F & B ANDINA SAC
A175: 46084 | B175: BK3764 | C175: 12183159 | D175: Diaz Menacho, Mayra Melisaa | E175: B6 NEN-No hizo pedido | F175: Off Tradicional | G175: Sales | H175: 1 | I175: 25 | J175: =VLOOKUP(C175,MAESTRO_CLIENTES!A:H,8,0) -> DARCY JIMENEZ | K175: =VLOOKUP(C175,MAESTRO_CLIENTES!A:Y,9,0) -> -11.990924 | L175: =VLOOKUP(C175,MAESTRO_CLIENTES!A:Y,10,0) -> -77.000385 | M175: =VLOOKUP(B175,Hoja1!B:C,2,0) -> F & B ANDINA SAC
A176: 46084 | B176: BK3764 | C176: 12792178 | D176: Felix Choqueccahuana, Ynes | E176: B4 NEN-Ausente | F176: Off Tradicional | G176: Customer | H176: 2 | I176: 15.027778 | J176: =VLOOKUP(C176,MAESTRO_CLIENTES!A:H,8,0) -> DARCY JIMENEZ | K176: =VLOOKUP(C176,MAESTRO_CLIENTES!A:Y,9,0) -> -11.992052 | L176: =VLOOKUP(C176,MAESTRO_CLIENTES!A:Y,10,0) -> -77.009386 | M176: =VLOOKUP(B176,Hoja1!B:C,2,0) -> F & B ANDINA SAC
A177: 46084 | B177: BK3761 | C177: 14322960 | D177: Pastipiqueos Italianos S.A.C | E177: C9 NEN-Error carga | F177: On High End | G177: Logistic | H177: 2 | I177: 44 | J177: =VLOOKUP(C177,MAESTRO_CLIENTES!A:H,8,0) -> VALERIA KORN | K177: =VLOOKUP(C177,MAESTRO_CLIENTES!A:Y,9,0) -> -12.050221 | L177: =VLOOKUP(C177,MAESTRO_CLIENTES!A:Y,10,0) -> -77.041669 | M177: =VLOOKUP(B177,Hoja1!B:C,2,0) -> JRGRODVAL DISTRIBUCIONES S.A.C.
A178: 46084 | B178: BK3723 | C178: 11121178 | D178: Supermercados Peruanos S.A. | E178: B8 NEN-Mal facturado | F178: Off Moderno | G178: Sales | H178: 1 | I178: 19 | J178: =VLOOKUP(C178,MAESTRO_CLIENTES!A:H,8,0) -> CHAVEZ HOLGUIN KENNER | K178: =VLOOKUP(C178,MAESTRO_CLIENTES!A:Y,9,0) -> -12.028806 | L178: =VLOOKUP(C178,MAESTRO_CLIENTES!A:Y,10,0) -> -77.030928 | M178: =VLOOKUP(B178,Hoja1!B:C,2,0) -> CORPORACION BREXIMAR S.A.C.
A179: 46084 | B179: BK3723 | C179: 13434885 | D179: Rurush Tamara, Francisca | E179: B4 NEN-Ausente | F179: Off Tradicional | G179: Customer | H179: 1 | I179: 7.75 | J179: =VLOOKUP(C179,MAESTRO_CLIENTES!A:H,8,0) -> HEIGER DONADONY CESPEDES CESPEDES | K179: =VLOOKUP(C179,MAESTRO_CLIENTES!A:Y,9,0) -> -12.036133 | L179: =VLOOKUP(C179,MAESTRO_CLIENTES!A:Y,10,0) -> -77.046583 | M179: =VLOOKUP(B179,Hoja1!B:C,2,0) -> CORPORACION BREXIMAR S.A.C.
A180: 46084 | B180: BK3723 | C180: 14024371 | D180: LAPA ESPINOZA, VIRGEN | E180: B4 NEN-Ausente | F180: Off Tradicional | G180: Customer | H180: 1 | I180: 10 | J180: =VLOOKUP(C180,MAESTRO_CLIENTES!A:H,8,0) -> GIOVANY RUBINOS VILCHEZ | K180: =VLOOKUP(C180,MAESTRO_CLIENTES!A:Y,9,0) -> -12.023021 | L180: =VLOOKUP(C180,MAESTRO_CLIENTES!A:Y,10,0) -> -77.027912 | M180: =VLOOKUP(B180,Hoja1!B:C,2,0) -> CORPORACION BREXIMAR S.A.C.
... A222: 46084 | B222: BK3760 | C222: 14376695 | D222: Quillas Chumpitaz, Pedro Juan | E222: B8 NEN-Mal facturado | F222: Off Tradicional | G222: Sales | H222: 1 | I222: 2 | J222: =VLOOKUP(C222,MAESTRO_CLIENTES!A:H,8,0) -> HEIGER DONADONY CESPEDES CESPEDES | K222: =VLOOKUP(C222,MAESTRO_CLIENTES!A:Y,9,0) -> -12.067132 | L222: =VLOOKUP(C222,MAESTRO_CLIENTES!A:Y,10,0) -> -77.051382 | M222: =VLOOKUP(B222,Hoja1!B:C,2,0) -> CORPORACION BREXIMAR S.A.C.
A223: 46084 | B223: BK3760 | C223: 14466813 | D223: #N/A | E223: C4 NEN-Mala Calidad | F223: #N/A | G223: Logistic | H223: 1 | I223: 1 | J223: =VLOOKUP(C223,MAESTRO_CLIENTES!A:H,8,0) -> #N/A | K223: =VLOOKUP(C223,MAESTRO_CLIENTES!A:Y,9,0) -> #N/A | L223: =VLOOKUP(C223,MAESTRO_CLIENTES!A:Y,10,0) -> #N/A | M223: =VLOOKUP(B223,Hoja1!B:C,2,0) -> CORPORACION BREXIMAR S.A.C.
A224: 46084 | B224: BK3780 | C224: 13725692 | D224: CHAMBERGO MANRIQUE, JANETH MARITZA | E224: B8 NEN-Mal facturado | F224: On Tradicional | G224: Sales | H224: 1 | I224: 4 | J224: =VLOOKUP(C224,MAESTRO_CLIENTES!A:H,8,0) -> HEIGER DONADONY CESPEDES CESPEDES | K224: =VLOOKUP(C224,MAESTRO_CLIENTES!A:Y,9,0) -> -12.05143 | L224: =VLOOKUP(C224,MAESTRO_CLIENTES!A:Y,10,0) -> -77.029797 | M224: =VLOOKUP(B224,Hoja1!B:C,2,0) -> SEGSOL S.A.C.
A225: 46084 | B225: BK3780 | C225: 13799233 | D225: Flores Palomino, Noemi Amalia | E225: B8 NEN-Mal facturado | F225: Off Tradicional | G225: Sales | H225: 2 | I225: 1.999998 | J225: =VLOOKUP(C225,MAESTRO_CLIENTES!A:H,8,0) -> HEIGER DONADONY CESPEDES CESPEDES | K225: =VLOOKUP(C225,MAESTRO_CLIENTES!A:Y,9,0) -> -12.054837 | L225: =VLOOKUP(C225,MAESTRO_CLIENTES!A:Y,10,0) -> -77.037204 | M225: =VLOOKUP(B225,Hoja1!B:C,2,0) -> SEGSOL S.A.C.
A226: 46084 | B226: BK3780 | C226: 14373611 | D226: Tiendas Tambo S.A.C. | E226: B8 NEN-Mal facturado | F226: Off Moderno | G226: Sales | H226: 1 | I226: 8 | J226: =VLOOKUP(C226,MAESTRO_CLIENTES!A:H,8,0) -> CHAVEZ HOLGUIN KENNER | K226: =VLOOKUP(C226,MAESTRO_CLIENTES!A:Y,9,0) -> -12.05435 | L226: =VLOOKUP(C226,MAESTRO_CLIENTES!A:Y,10,0) -> -77.038974 | M226: =VLOOKUP(B226,Hoja1!B:C,2,0) -> SEGSOL S.A.C.
A227: 46084 | B227: BK3780 | C227: 14398201 | D227: Carrion Pezua, Yudith Vanesa | E227: C9 NEN-Error carga | F227: Off Tradicional | G227: Logistic | H227: 1 | I227: 1 | J227: =VLOOKUP(C227,MAESTRO_CLIENTES!A:H,8,0) -> HEIGER DONADONY CESPEDES CESPEDES | K227: =VLOOKUP(C227,MAESTRO_CLIENTES!A:Y,9,0) -> -12.05599 | L227: =VLOOKUP(C227,MAESTRO_CLIENTES!A:Y,10,0) -> -77.031724 | M227: =VLOOKUP(B227,Hoja1!B:C,2,0) -> SEGSOL S.A.C.
A228: 46084 | B228: BK3732 | C228: 13796236 | D228: Rosales Flores, Lucia Mariela | E228: B1 NEN-Cerrado | F228: Off Tradicional | G228: Customer | H228: 1 | I228: 12.225001 | J228: =VLOOKUP(C228,MAESTRO_CLIENTES!A:H,8,0) -> MIGUEL HERRERA | K228: =VLOOKUP(C228,MAESTRO_CLIENTES!A:Y,9,0) -> -11.965625 | L228: =VLOOKUP(C228,MAESTRO_CLIENTES!A:Y,10,0) -> -76.982416 | M228: =VLOOKUP(B228,Hoja1!B:C,2,0) -> F & B ANDINA SAC
A229: 46084 | B229: BK3732 | C229: 11649857 | D229: Ochoa Concepcion, Harumi | E229: C4 NEN-Mala Calidad | F229: Off Tradicional | G229: Logistic | H229: 1 | I229: 1 | J229: =VLOOKUP(C229,MAESTRO_CLIENTES!A:H,8,0) -> DARCY JIMENEZ | K229: =VLOOKUP(C229,MAESTRO_CLIENTES!A:Y,9,0) -> -11.97675 | L229: =VLOOKUP(C229,MAESTRO_CLIENTES!A:Y,10,0) -> -76.99819 | M229: =VLOOKUP(B229,Hoja1!B:C,2,0) -> F & B ANDINA SAC
A230: 46084 | B230: BK3732 | C230: 12497451 | D230: Giron Ramos, Guillermo | E230: C9 NEN-Error carga | F230: Off Tradicional | G230: Logistic | H230: 1 | I230: 1 | J230: =VLOOKUP(C230,MAESTRO_CLIENTES!A:H,8,0) -> DARCY JIMENEZ | K230: =VLOOKUP(C230,MAESTRO_CLIENTES!A:Y,9,0) -> -11.982785 | L230: =VLOOKUP(C230,MAESTRO_CLIENTES!A:Y,10,0) -> -76.99431 | M230: =VLOOKUP(B230,Hoja1!B:C,2,0) -> F & B ANDINA SAC
A231: 46084 | B231: BK3734 | C231: 10168403 | D231: Palomino Huallparimachi, Elvis | E231: B6 NEN-No hizo pedido | F231: Off Tradicional | G231: Sales | H231: 1 | I231: 6 | J231: =VLOOKUP(C231,MAESTRO_CLIENTES!A:H,8,0) -> HEIGER DONADONY CESPEDES CESPEDES | K231: =VLOOKUP(C231,MAESTRO_CLIENTES!A:Y,9,0) -> -12.076 | L231: =VLOOKUP(C231,MAESTRO_CLIENTES!A:Y,10,0) -> -77.05141 | M231: =VLOOKUP(B231,Hoja1!B:C,2,0) -> CORPORACION BREXIMAR S.A.C.
A232: 46084 | B232: BK3734 | C232: 12143474 | D232: Salcedo Casachagua, Edith Mariela | E232: B6 NEN-No hizo pedido | F232: Off Tradicional | G232: Sales | H232: 1 | I232: 2 | J232: =VLOOKUP(C232,MAESTRO_CLIENTES!A:H,8,0) -> HEIGER DONADONY CESPEDES CESPEDES | K232: =VLOOKUP(C232,MAESTRO_CLIENTES!A:Y,9,0) -> -12.076201 | L232: =VLOOKUP(C232,MAESTRO_CLIENTES!A:Y,10,0) -> -77.046884 | M232: =VLOOKUP(B232,Hoja1!B:C,2,0) -> CORPORACION BREXIMAR S.A.C.
A233: 46084 | B233: BK3734 | C233: 14435239 | D233: Luc Gud S.A.C. | E233: B1 NEN-Cerrado | F233: On Mid High End | G233: Customer | H233: 1 | I233: 4 | J233: =VLOOKUP(C233,MAESTRO_CLIENTES!A:H,8,0) -> ESTEBAN FERNANDEZ | K233: =VLOOKUP(C233,MAESTRO_CLIENTES!A:Y,9,0) -> -12.075299 | L233: =VLOOKUP(C233,MAESTRO_CLIENTES!A:Y,10,0) -> -77.044776 | M233: =VLOOKUP(B233,Hoja1!B:C,2,0) -> CORPORACION BREXIMAR S.A.C.
A234: 46084 | B234: BK3718 | C234: 14199686 | D234: Amaru Solis, David Javier | E234: C9 NEN-Error carga | F234: On Mid High End | G234: Logistic | H234: 3 | I234: 11.667261 | J234: =VLOOKUP(C234,MAESTRO_CLIENTES!A:H,8,0) -> ESTEBAN FERNANDEZ | K234: =VLOOKUP(C234,MAESTRO_CLIENTES!A:Y,9,0) -> -12.058946 | L234: =VLOOKUP(C234,MAESTRO_CLIENTES!A:Y,10,0) -> -77.03317 | M234: =VLOOKUP(B234,Hoja1!B:C,2,0) -> CORPORACION BREXIMAR S.A.C.
...

Sheet Hoja1
A1: Fecha | B1: Ruta | C1: Empresario
A2: 46083 | B2: BK3712 | C2: SEGSOL S.A.C.
A3: 46083 | B3: BK3712 | C3: SEGSOL S.A.C.
A4: 46083 | B4: BK3712 | C4: SEGSOL S.A.C.
A5: 46083 | B5: BK3712 | C5: SEGSOL S.A.C.
A6: 46083 | B6: BK3712 | C6: SEGSOL S.A.C.
A7: 46083 | B7: BK3712 | C7: SEGSOL S.A.C.
A8: 46083 | B8: BK3712 | C8: SEGSOL S.A.C.
A9: 46083 | B9: BK3712 | C9: SEGSOL S.A.C.
A10: 46083 | B10: BK3712 | C10: SEGSOL S.A.C.
A11: 46083 | B11: BK3760 | C11: CORPORACION BREXIMAR S.A.C.
A12: 46083 | B12: BK3760 | C12: CORPORACION BREXIMAR S.A.C.
A13: 46083 | B13: BK3760 | C13: CORPORACION BREXIMAR S.A.C.
... A2166: 46098 | B2166: BK3755 | C2166: CORPORACION BREXIMAR S.A.C.

Sheet MAESTRO_CLIENTES
A1: cliente_id | B1: nombre | C1: direccion_geo | D1: distrito | E1: telefono | F1: canal | G1: zona_pem | H1: supervisor | I1: Latitud | J1: Longitud
A2: 10167450 | B2: Alvarado Delgado, Puol Jimmy | C2: Av. Arenales 2406 LINCE | D2: LINCE | E2: 980855740 | F2: Off Tradicional | G2: PEX578 | H2: HEIGER DONADONY CESPEDES CESPEDES | I2: -12.08826 | J2: -77.03513
A3: 10169835 | B3: Machuca Canales, Elsa | C3: Jr. Leticia 539 LIMA | D3: LIMA | E3: 978631416 | F3: Off Tradicional | G3: PEX525 | H3: HEIGER DONADONY CESPEDES CESPEDES | I3: -12.056713 | J3: -77.031164
A4: 10171859 | B4: Mejias Reyes, Lucy Clorinda | C4: Aa.hh. Ramon Carcamo Mz E3 Lt 1 LIMA | D4: LIMA | E4: 934887068 | F4: Off Tradicional | G4: PEX738 | H4: HEIGER DONADONY CESPEDES CESPEDES | I4: -12.042846 | J4: -77.050544
A5: 10172655 | B5: Libreria Bazar Amaya E.I.R.L. | C5: Av. EspaÃ±a 0487 LIMA | D5: LIMA | E5: 958340251 | F5: Off Tradicional | G5: PEMA28 | H5: HEIGER DONADONY CESPEDES CESPEDES | I5: -12.058265 | J5: -77.041321
A6: 10173198 | B6: Zelada Abanto, Severo Hermogenes | C6: Jr. Moquegua 0198 LIMA | D6: LIMA | E6: 990704643 | F6: On Tradicional | G6: PEX525 | H6: HEIGER DONADONY CESPEDES CESPEDES | I6: -12.04941 | J6: -77.034998
A7: 10177074 | B7: Sima Tinoco, Julio Ascencion | C7: Jr. Risso 0757 LINCE | D7: LINCE | E7: 949731304 | F7: Off Tradicional | G7: PEMA29 | H7: HEIGER DONADONY CESPEDES CESPEDES | I7: -12.084858 | J7: -77.028535
A8: 10178439 | B8: Olivas Trejo, Demetria Teodora | C8: Aa.hh. Perez De Cuellar Mz K-1 Lt 0 SAN JUAN DE LURIGANCHO | D8: SAN JUAN DE LURIGANCHO | E8: 923876940 | F8: Off Tradicional | G8: PEMA40 | H8: MIGUEL HERRERA | I8: -11.955465 | J8: -76.96919
A9: 10179265 | B9: Deudor De Pacheco, Epifania | C9: Jr. Perez De Tudela Mz F-17 Lt 010 SAN JUAN DE LURIGANCHO | D9: SAN JUAN DE LURIGANCHO | E9: 995925078 | F9: Off Tradicional | G9: PEX504 | H9: MIGUEL HERRERA | I9: -11.95236 | J9: -76.98421
A10: 10183416 | B10: Chirinos Mallqui, Sandra Karen | C10: Jr. Las Margaritas Mz T Lt 14 SAN JUAN DE LURIGANCHO | D10: SAN JUAN DE LURIGANCHO | E10: 990819522 | F10: Off Tradicional | G10: PEX523 | H10: DARCY JIMENEZ | I10: -12.00832 | J10: -76.98797
A11: 10184748 | B11: Rojas Huarcaya, Teodora | C11: Aa.hh. La Gruta Mz GU13 Lt 001 SAN JUAN DE LURIGANCHO | D11: SAN JUAN DE LURIGANCHO | E11: 948373684 | F11: Off Tradicional | G11: PEMA18 | H11: MIGUEL HERRERA | I11: -11.96641 | J11: -76.97517
A12: 10190255 | B12: Espinoza CastaÃ±eda, Noemi Demetria | C12: Conj.Hab. Cristo Rey Mz A Lt 28 SAN JUAN DE LURIGANCHO | D12: SAN JUAN DE LURIGANCHO | E12: 960746106 | F12: Off Tradicional | G12: PEMA40 | H12: MIGUEL HERRERA | I12: -11.939046 | J12: -77.009017
A13: 10191165 | B13: Rayme Rivas, Manuel Filiberto | C13: Coop. Sagrada Familia Mz A Lt 17 SAN JUAN DE LURIGANCHO | D13: SAN JUAN DE LURIGANCHO | E13: 013874666 | F13: Off Tradicional | G13: PEMA27 | H13: DARCY JIMENEZ | I13: -11.9762 | J13: -76.98774
A14: 10194648 | B14: Leon Zarate, Alcidas Rubila | C14: Jr. Los Robles 0421 SAN JUAN DE LURIGANCHO | D14: SAN JUAN DE LURIGANCHO | E14: 952380426 | F14: Off Tradicional | G14: PEX507 | H14: GIOVANY RUBINOS VILCHEZ | I14: -11.975028 | J14: -77.014133
A15: 10196293 | B15: Flores Garnique, Victoria | C15: Av. Canto Grande 2372 SAN JUAN DE LURIGANCHO | D15: SAN JUAN DE LURIGANCHO | E15: 01 2533792 | F15: Off Tradicional | G15: PEM745 | H15: SUPERVISOR PRUEBA | I15: -11.99089 | J15: -77.01507
A16: 10196517 | B16: Cardenas Guerrero, Juan De La Cruz | C16: Av. Los Ciruelos 435A SAN JUAN DE LURIGANCHO | D16: SAN JUAN DE LURIGANCHO | E16: 013876772 | F16: Off Tradicional | G16: PEMA10 | H16: DARCY JIMENEZ | I16: -11.98331 | J16: -77.005037
A17: 10196866 | B17: Hidalgo Pizarro, Rigoberto Samuel | C17: SV Villa Rosario Mz I Lt 5 SAN JUAN DE LURIGANCHO | D17: SAN JUAN DE LURIGANCHO | E17: 985620839 | F17: Off Tradicional | G17: PEMA17 | H17: DARCY JIMENEZ | I17: -11.999732 | J17: -76.995965
A18: 10196937 | B18: Sanchez Lozano, Lola Rosalbina | C18: Av. Clorinda Mattos Mz G1 Lt 6 SAN JUAN DE LURIGANCHO | D18: SAN JUAN DE LURIGANCHO | E18: 949244452 | F18: Off Tradicional | G18: PEMA55 | H18: GIOVANY RUBINOS VILCHEZ | I18: -11.96965 | J18: -77.00654
A19: 10199917 | B19: Veliz Vicharra, Teofilo Inocente | C19: Av. Los Tusilagos 0560 SAN JUAN DE LURIGANCHO | D19: SAN JUAN DE LURIGANCHO | E19: 014581441 | F19: Off Tradicional | G19: PEX522 | H19: DARCY JIMENEZ | I19: -12.012423 | J19: -77.010297
A20: 10200777 | B20: Cajo Rocha, Eulalia Margot | C20: Aa.hh. J.C.Mariategui Mz H3 Lt 35 SAN JUAN DE LURIGANCHO | D20: SAN JUAN DE LURIGANCHO | E20: 931323313 | F20: Off Tradicional | G20: PEMA18 | H20: MIGUEL HERRERA | I20: -11.943235 | J20: -76.983842
A21: 10201816 | B21: De La Cruz De Paucar, Rosaura | C21: Jr. San Juan De Pacheco Mz A Lt 008 SAN JUAN DE LURIGANCHO | D21: SAN JUAN DE LURIGANCHO | E21: 987636688 | F21: Off Tradicional | G21: PEX522 | H21: DARCY JIMENEZ | I21: -12.01907 | J21: -76.95501
A22: 10202779 | B22: Perez Tume, Claudio | C22: Jr. Los Amautas 1032 SAN JUAN DE LURIGANCHO | D22: SAN JUAN DE LURIGANCHO | E22: 991534386 | F22: Off Tradicional | G22: PEMA07 | H22: DARCY JIMENEZ | I22: -12.0251 | J22: -76.99615
A23: 10230347 | B23: Reyes Suarez, Minlly Vanessa | C23: Jr. Martin Olaya 941 SAN MARTIN DE PORRES | D23: SAN MARTIN DE PORRES | E23: 950104825 | F23: On Tradicional | G23: PEMA49 | H23: GIOVANY RUBINOS VILCHEZ | I23: -12.03138 | J23: -77.053862
A24: 10237367 | B24: Rubio Delgado, Jaime | C24: Ca. 14 0302 RIMAC | D24: RIMAC | E24: 986156970 | F24: Off Tradicional | G24: PEMA55 | H24: GIOVANY RUBINOS VILCHEZ | I24: -12.02564 | J24: -77.03139
A25: 10238519 | B25: Tello Lizarraga, Carlos Augusto | C25: Jr. Loreto 0594 RIMAC | D25: RIMAC | E25: 960602899 | F25: On Tradicional | G25: PEM159 | H25: ESTEBAN FERNANDEZ | I25: -12.042652 | J25: -77.024367
A26: 10580688 | B26: Jayo Villasana, Haydee Flora | C26: Ca. Ancash Mz C Lt 3 SAN JUAN DE LURIGANCHO | D26: SAN JUAN DE LURIGANCHO | E26: 922153038 | F26: Off Tradicional | G26: PEMA13 | H26: DARCY JIMENEZ | I26: -12.03248 | J26: -77.01422
A27: 10638822 | B27: Lima Lopez, Felix Rogelio | C27: Av. Jardines Este Mz C Lt 9 SAN JUAN DE LURIGANCHO | D27: SAN JUAN DE LURIGANCHO | E27: 934206377 | F27: Off Tradicional | G27: PEMA27 | H27: DARCY JIMENEZ | I27: -12.004262 | J27: -77.002738
A28: 10856119 | B28: Meza Flores, Percy Jesus | C28: Avenida progreso santa rosita mz 10 LIMA | D28: SAN JUAN DE LURIGANCHO | E28: 992732203 | F28: Off Tradicional | G28: PEMA13 | H28: DARCY JIMENEZ | I28: -12.03192 | J28: -77.01239
A29: 10931513 | B29: Lopez Sevillano, Viky | C29: Mz Dh Lt 9 Av Anchas Palomar SAN JUAN DE LURIGANCHO | D29: SAN JUAN DE LURIGANCHO | E29: 925071671 | F29: Off Tradicional | G29: PEMA37 | H29: MIGUEL HERRERA | I29: -11.918048 | J29: -76.953395
A30: 10981379 | B30: Restaurant Y Anticucheria La K-Ravana E.I.R.L. | C30: Av. Las Flores 190 SAN JUAN DE LURIGANCHO | D30: SAN JUAN DE LURIGANCHO | E30: 941711326 | F30: Off Tradicional | G30: PEX511 | H30: GIOVANY RUBINOS VILCHEZ | I30: -11.972501 | J30: -77.004134
A31: 11026090 | B31: Camacho Licona, Menelia | C31: Jr. Del Cruce Mz. O1 Lote 11 SAN JUAN DE LURIGANCHO | D31: SAN JUAN DE LURIGANCHO | E31: 946293039 | F31: Off Tradicional | G31: PEMA18 | H31: MIGUEL HERRERA | I31: -11.948768 | J31: -76.978828
A32: 11026601 | B32: Huaman Tapara, Delia Paulina | C32: Jr. Del Cerrito Mz. Q17 Lote 15 SAN JUAN DE LURIGANCHO | D32: SAN JUAN DE LURIGANCHO | E32: 977449768 | F32: Off Tradicional | G32: PEMA18 | H32: MIGUEL HERRERA | I32: -11.9385 | J32: -76.99353
A33: 11063836 | B33: Panta NiÃ±o De Infanzon, Yolanda | C33: Jr. Las Gravas 2065 SAN JUAN DE LURIGANCHO | D33: SAN JUAN DE LURIGANCHO | E33: 014597022 | F33: Off Tradicional | G33: PEMA10 | H33: DARCY JIMENEZ | I33: -11.997292 | J33: -77.007773
A34: 11135690 | B34: Silva Guevara, Manuel Jesus | C34: La Hoyada 188 RIMAC | D34: RIMAC | E34: 994374424 | F34: Off Tradicional | G34: PEMA55 | H34: GIOVANY RUBINOS VILCHEZ | I34: -12.026643 | J34: -77.031058
A35: 11177378 | B35: Cabrera Espinoza, Juana Liduvina | C35: Jr. Las Crisocalas 248 SAN JUAN DE LURIGANCHO | D35: SAN JUAN DE LURIGANCHO | E35: 956656209 | F35: Off Tradicional | G35: PEX523 | H35: DARCY JIMENEZ | I35: -11.986797 | J35: -77.005242
A36: 11195232 | B36: Inversiones Cusami E.I.R.L. | C36: Jiron Enrique Barron 1489 LINCE | D36: LIMA | E36: 990885803 | F36: Off Tradicional | G36: PEMA28 | H36: HEIGER DONADONY CESPEDES CESPEDES | I36: -12.078906 | J36: -77.032456
A37: 11453272 | B37: Sistemas Lurin S.A.C. | C37: Ca. Juan Figari 135 MIRAFLORES | D37: MIRAFLORES | E37: 939712061 | F37: Off Tradicional | G37: PEMA28 | H37: HEIGER DONADONY CESPEDES CESPEDES | I37: -12.122182 | J37: -77.031276
A38: 11592838 | B38: Terrazo Hinostroza, Kevin Aldahir | C38: Jr. Nevado Ausangate Mz A Lt 14 SAN JUAN DE LURIGANCHO | D38: SAN JUAN DE LURIGANCHO | E38: 946533217 | F38: Off Tradicional | G38: PEX509 | H38: GIOVANY RUBINOS VILCHEZ | I38: -11.98294 | J38: -77.01414
A39: 11650033 | B39: Veramendi Silvestre, Anabel Fabiola | C39: Ca. 5 Mz B Lt 28 SAN JUAN DE LURIGANCHO | D39: SAN JUAN DE LURIGANCHO | E39: 901403069 | F39: Off Tradicional | G39: PEMA27 | H39: DARCY JIMENEZ | I39: -12.019643 | J39: -76.967072
A40: 11750847 | B40: Cardenas Valdivieso, Roman Anthony | C40: Ca. Algarrobos Mz A Lt 27 EL AGUSTINO | D40: EL AGUSTINO | E40: 915156480 | F40: On Tradicional | G40: PEM159 | H40: ESTEBAN FERNANDEZ | I40: -12.039303 | J40: -76.995902
...
